Workbook
Name location: Lists!$A$1:$C$9
Name location_price_variance: raw_location_price_variance!$A$1:$L$8016
Name menu_engineering: raw_menu_engineering!$A$1:$K$2638
Name menu_profitability_by_location: raw_menu_profitability!$A$1:$I$132
Name menu_profitability_by_location_1: raw_menu_profitability!$A$1:$I$132
Name menu_profitability_by_location_2: raw_menu_profitability!$A$1:$H$132

Sheet Overview
B2: Sheet | C2: Posting Line | D2: Question | E2: Source | F2: Main Measures
B3: =HYPERLINK("#RPM!A1", "RPM") -> RPM | C3: Support the development, costing review, and maintenance of RPMs (Recipes, Pricing, and Margins) | D3: What does each active dish cost, sell for and earn per serving at each location? | E3: menu_profitability_by_location | F3: menu price, cost per serving, gross profit per unit, margin percent
B4: =HYPERLINK("#Menu_Performance!A1", "Menu_Performance") -> Menu_Performance | C4: Monitor and analyze virtual menu performance | D4: Which dish earns the most and the least profit per location per time window? | E4: menu_engineering | F4: quantity sold, profit dollars, cost dollars, gross profit dollars | G4: Note: records have been filtered from 2025-02-01 to but not including 2026-10-01
B5: =HYPERLINK("#Ingredient_Cost!A1", "Ingredient_Cost") -> Ingredient_Cost | C5: Monitor ingredient cost fluctuations | D5: How does each ingredient’s price per location move month to month? | E5: location_price_variance | F5: average price paid, quantity purchased, purchase dollars, and min and max price | G5: Note: records have been filtered from 2025-02-01 to but not including 2026-10-01
B6: =HYPERLINK("#KPI_Reporting!A1", "KPI_Reporting") -> KPI_Reporting | C6: Generate forecasting, KPI, operational reports and magin trends | D6: Which locations keep the highest share of sales after food cost? | E6: location_monthly_performance | F6: sales_dollars, actual food cost, theoretical food cost | G6: Note: records have been filtered from 2025-02-01 to but not including 2026-10-01

Sheet Lists
A1: location_name | B1: location_id | C1: region_id | E1: month | F1: year | G1: month_start
A2: Eataly Flatiron | B2: 1 | C2: 1 | E2: =MOD(ROW()-1,12)+1 -> 2 | F2: 2025 | G2: =DATE(F2, E2, 1) -> 45689
A3: Eataly Downtown NYC | B3: 2 | C3: 1 | E3: =MOD(ROW()-1,12)+1 -> 3 | F3: 2025 | G3: =DATE(F3, E3, 1) -> 45717
A4: Eataly Boston | B4: 3 | C4: 1 | E4: =MOD(ROW()-1,12)+1 -> 4 | F4: 2025 | G4: =DATE(F4, E4, 1) -> 45748
A5: Eataly Chicago | B5: 4 | C5: 2 | E5: =MOD(ROW()-1,12)+1 -> 5 | F5: 2025 | G5: =DATE(F5, E5, 1) -> 45778
A6: Eataly Los Angeles | B6: 5 | C6: 3 | E6: =MOD(ROW()-1,12)+1 -> 6 | F6: 2025 | G6: =DATE(F6, E6, 1) -> 45809
A7: Eataly Las Vegas | B7: 6 | C7: 3 | E7: =MOD(ROW()-1,12)+1 -> 7 | F7: 2025 | G7: =DATE(F7, E7, 1) -> 45839
A8: Eataly Dallas | B8: 7 | C8: 4 | E8: =MOD(ROW()-1,12)+1 -> 8 | F8: 2025 | G8: =DATE(F8, E8, 1) -> 45870
A9: Eataly San Jose | B9: 8 | C9: 3 | E9: =MOD(ROW()-1,12)+1 -> 9 | F9: 2025 | G9: =DATE(F9, E9, 1) -> 45901
E10: =MOD(ROW()-1,12)+1 -> 10 | F10: 2025 | G10: =DATE(F10, E10, 1) -> 45931
E11: =MOD(ROW()-1,12)+1 -> 11 | F11: 2025 | G11: =DATE(F11, E11, 1) -> 45962
E12: =MOD(ROW()-1,12)+1 -> 12 | F12: 2025 | G12: =DATE(F12, E12, 1) -> 45992
E13: =MOD(ROW()-1,12)+1 -> 1 | F13: 2026 | G13: =DATE(F13, E13, 1) -> 46023
E14: =MOD(ROW()-1,12)+1 -> 2 | F14: 2026 | G14: =DATE(F14, E14, 1) -> 46054
E15: =MOD(ROW()-1,12)+1 -> 3 | F15: 2026 | G15: =DATE(F15, E15, 1) -> 46082
E16: =MOD(ROW()-1,12)+1 -> 4 | F16: 2026 | G16: =DATE(F16, E16, 1) -> 46113
E17: =MOD(ROW()-1,12)+1 -> 5 | F17: 2026 | G17: =DATE(F17, E17, 1) -> 46143
E18: =MOD(ROW()-1,12)+1 -> 6 | F18: 2026 | G18: =DATE(F18, E18, 1) -> 46174
E19: =MOD(ROW()-1,12)+1 -> 7 | F19: 2026 | G19: =DATE(F19, E19, 1) -> 46204
E20: =MOD(ROW()-1,12)+1 -> 8 | F20: 2026 | G20: =DATE(F20, E20, 1) -> 46235
E21: =MOD(ROW()-1,12)+1 -> 9 | F21: 2026 | G21: =DATE(F21, E21, 1) -> 46266

Sheet Findings
B1: Note: records have been filtered from 2025-02-01 to but not including 2026-10-01 | D1: prices were constant over the window in this data, so the differences between locations come from price levels and ingredient costs, not price changes.
B2: Menu Performance
B4: Proscuitto e Melone Findings What I saw: Out of the 5 locations that Proscuitto e Melone is served, 3 locations have it marked as DOG. In all 5 locations, profit was steadily between 6 - 11%, or $0.98 to $1.76 below the benchmark and the popularity varied greatly, from 19.77% below the threshold to 13.98% above the threshold. The dish was least popular in locations 7 and 8 and most popular in locations Flatiron and Boston. Why it matters: The shortfall is $0.98 to $1.76 per plate, about $7,200 of profit over 20 months across Flatiron and Chicago locations, $12,300 across all locations, excluding Downtown NYC. Recommended Action: I would consider replacing the dish on the menu in Dallas and San Jose because the popularity is 18-20% below the threshold. This assumes the replacement sells at least as well, which this data cannot test. I would review the food cost for the ingredients for this dish and raise prices if needed to close that gap. Caveat: Please note that the recipe cost does not include overhead and labor costs, therefore the profits may differ.
F13: Proscuitto e Melone
F14: Evidence
F15: Location | G15: category | H15: threshold | I15: units_sold | J15: share_of_units | K15: pct_of_threshold | L15: benchmark | M15: profit_per_plate | N15: pct_of_benchmark | O15: profit_difference | P15: loss_dollars
F16: {=Lists!$A$2:$A$9} -> Eataly Flatiron | G16: PLOWHORSE | H16: 0.038888889 | I16: 2714 | J16: 0.044326849 | K16: =IF(G16="NO SALE", "-", IF(G16="NOT ON MENU", "-", (J16-H16)/H16)) -> 0.13983327 | L16: 16.130947 | M16: 14.375911 | N16: =(M16-L16)/L16 -> -0.10879936 | O16: =L16*N16 -> -1.7550368 | P16: =I16*O16 -> -4763.1698
F17: Eataly Downtown NYC | G17: DROPPED | H17: 0.04375 | I17: 491 | J17: 0.0102 | K17: =IF(G17="NO SALE", "-", IF(G17="NOT ON MENU", "-", (J17-H17)/H17)) -> -0.76685714 | L17: 15.837499 | M17: 14.61 | N17: =(M17-L17)/L17 -> -0.077505833 | O17: =L17*N17 -> -1.2274985 | P17: -
F18: Eataly Boston | G18: NOT ON MENU | H18: - | I18: - | J18: - | K18: =IF(G18="NO SALE", "-", IF(G18="NOT ON MENU", "-", (J18-H18)/H18)) -> - | L18: - | M18: 0 | N18: - | O18: - | P18: -
F19: Eataly Chicago | G19: PLOWHORSE | H19: 0.04375 | I19: 1798 | J19: 0.0494 | K19: =IF(G19="NO SALE", "-", IF(G19="NOT ON MENU", "-", (J19-H19)/H19)) -> 0.12914286 | L19: 15.532631 | M19: 14.16 | N19: =(M19-L19)/L19 -> -0.088370807 | O19: =L19*N19 -> -1.3726311 | P19: =I19*O19 -> -2467.9908
F20: Eataly Los Angeles | G20: NOT ON MENU | H20: - | I20: - | J20: - | K20: =IF(G20="NO SALE", "-", IF(G20="NOT ON MENU", "-", (J20-H20)/H20)) -> - | L20: - | M20: 0 | N20: - | O20: - | P20: -
F21: Eataly Las Vegas | G21: DOG | H21: 0.038888889 | I21: 1954 | J21: 0.0372 | K21: =IF(G21="NO SALE", "-", IF(G21="NOT ON MENU", "-", (J21-H21)/H21)) -> -0.043428571 | L21: 16.695705 | M21: 15.07 | N21: =(M21-L21)/L21 -> -0.097372629 | O21: =L21*N21 -> -1.6257047 | P21: =I21*O21 -> -3176.6269
F22: Eataly Dallas | G22: DOG | H22: 0.038888889 | I22: 984 | J22: 0.032 | K22: =IF(G22="NO SALE", "-", IF(G22="NOT ON MENU", "-", (J22-H22)/H22)) -> -0.17714286 | L22: 13.48591 | M22: 12.22 | N22: =(M22-L22)/L22 -> -0.093869069 | O22: =L22*N22 -> -1.2659098 | P22: =I22*O22 -> -1245.6552
F23: Eataly San Jose | G23: DOG | H23: 0.038888889 | I23: 623 | J23: 0.0312 | K23: =IF(G23="NO SALE", "-", IF(G23="NOT ON MENU", "-", (J23-H23)/H23)) -> -0.19771429 | L23: 15.20019 | M23: 14.22 | N23: =(M23-L23)/L23 -> -0.064485379 | O23: =L23*N23 -> -0.98019001 | P23: =I23*O23 -> -610.65838
O24: total_shortfall | P24: =SUM(P16:P23) -> -12264.101
B26: Osso Buco Findings What I saw: Out of the 6 locations that Osso Buco is served, the dish is below its location's threshold. The popularity ranges from 27% to 48% below the threshold. In Boston, this dish is furthest below its threshold and closest to its threshold in Las Vegas. Despite selling relatively few units between February 2025 and September 2026, the dish remains highly profitable. The profit ranges from 91.13% above the benchmark in San Jose to 104.19% in Dallas. Osso Buco has profited about $92,500 above the benchmark across all locations that it is sold between February 2025 and September 2026, making it a highly profitable dish. Why it matters: Each plate profits between $13 and $16 above the benchmark. If more plates sold, each plate would carry that. Recommended Action: I would consider having the servers push the dish through suggestion at the Las Vegas location and track the dishes current share and threshold. I recommend also tracking the total gross profit to determine if increased Osso Buco sales result in a better dish losing sales. Caveat: Please note that the recipe cost does not include overhead and labor costs, therefore the profits may differ. Osso Buco is has the lowest margin % in the RPM sheet at about 60% to 65% but remains highly profitable across locations due to it's high menu price.
F35: Osso Buco
F36: Evidence
F37: Location | G37: category | H37: threshold | I37: units_sold | J37: share_of_units | K37: pct_of_threshold | L37: benchmark | M37: profit_per_plate | N37: pct_of_benchmark | O37: profit_difference | P37: profit_above_benchmark
F38: {=Lists!$A$2:$A$9} -> Eataly Flatiron | G38: PUZZLE | H38: 0.038888889 | I38: 1561 | J38: 0.025495288 | K38: =IF(G38="NO SALE", "-", IF(G38="NOT ON MENU", "-", (J38-H38)/H38)) -> -0.34440688 | L38: 16.130947 | M38: 31.552857 | N38: =(M38-L38)/L38 -> 0.95604486 | O38: =L38*N38 -> 15.421909 | P38: =I38*O38 -> 24073.601
F39: Eataly Downtown NYC | G39: NOT ON MENU | H39: - | I39: - | J39: - | K39: =IF(G39="NO SALE", "-", IF(G39="NOT ON MENU", "-", (J39-H39)/H39)) -> - | L39: - | M39: - | N39: - | O39: - | P39: -
F40: Eataly Boston | G40: PUZZLE | H40: 0.05 | I40: 881 | J40: 0.025946105 | K40: =IF(G40="NO SALE", "-", IF(G40="NOT ON MENU", "-", (J40-H40)/H40)) -> -0.4810779 | L40: 15.18 | M40: 29.756244 | N40: =(M40-L40)/L40 -> 0.96022691 | O40: =L40*N40 -> 14.576244 | P40: =I40*O40 -> 12841.671
F41: Eataly Chicago | G41: PUZZLE | H41: 0.04375 | I41: 1091 | J41: 0.02999725 | K41: =IF(G41="NO SALE", "-", IF(G41="NOT ON MENU", "-", (J41-H41)/H41)) -> -0.31434856 | L41: 15.532631 | M41: 30.875003 | N41: =(M41-L41)/L41 -> 0.98775099 | O41: =L41*N41 -> 15.342372 | P41: =I41*O41 -> 16738.528
F42: Eataly Los Angeles | G42: NOT ON MENU | H42: - | I42: - | J42: - | K42: =IF(G42="NO SALE", "-", IF(G42="NOT ON MENU", "-", (J42-H42)/H42)) -> - | L42: - | M42: - | N42: - | O42: - | P42: -
F43: Eataly Las Vegas | G43: PUZZLE | H43: 0.038888889 | I43: 1494 | J43: 0.028462564 | K43: =IF(G43="NO SALE", "-", IF(G43="NOT ON MENU", "-", (J43-H43)/H43)) -> -0.26810549 | L43: 16.695705 | M43: 32.804299 | N43: =(M43-L43)/L43 -> 0.96483467 | O43: =L43*N43 -> 16.108595 | P43: =I43*O43 -> 24066.241
F44: Eataly Dallas | G44: PUZZLE | H44: 0.038888889 | I44: 646 | J44: 0.021019067 | K44: =IF(G44="NO SALE", "-", IF(G44="NOT ON MENU", "-", (J44-H44)/H44)) -> -0.45950971 | L44: 13.48591 | M44: 27.536239 | N44: =(M44-L44)/L44 -> 1.0418525 | O44: =L44*N44 -> 14.050329 | P44: =I44*O44 -> 9076.5124
F45: Eataly San Jose | G45: PUZZLE | H45: 0.038888889 | I45: 410 | J45: 0.020521548 | K45: =IF(G45="NO SALE", "-", IF(G45="NOT ON MENU", "-", (J45-H45)/H45)) -> -0.47230306 | L45: 15.20019 | M45: 29.051793 | N45: =(M45-L45)/L45 -> 0.91127828 | O45: =L45*N45 -> 13.851603 | P45: =I45*O45 -> 5679.1573
O46: total_profit_above_benchmark | P46: =SUM(P38:P45) -> 92475.71

Sheet RPM
D1: check_sum_menu_price | E1: =SUM(E:E) -> 2704.65 | G1: Target Margin | H1: 0.65 | I1: RPM data rows | J1: =COUNTA(A:A) - 1 -> 131 | L1: Note:
D2: raw_check_sum | E2: =raw_menu_profitability!L3 -> 2692 | G2: count under target | H2: =COUNTIF(J:J, 1) -> 12 | I2: Raw data rows | J2: =COUNTA(raw_menu_profitability!A:A) -1 -> 131 | L2: costs are most recent
L3: prices are today's menu price
A4: location_id | B4: recipe_id | C4: Helper | D4: location_name | E4: menu_price | F4: recipe_name | G4: cost_per_serving | H4: gross_profit_per_unit | I4: profit_margin_pct | J4: margin_flag | L4: units are all-time
A5: 1 | B5: 1 | C5: =(A5&", "& B5) -> 1, 1 | D5: =INDEX(raw_menu_profitability!$B:$B, MATCH(C5, raw_menu_profitability!$J:$J, 0)) -> Eataly Flatiron | E5: =INDEX(raw_menu_profitability!$F:$F, MATCH(C5, raw_menu_profitability!$J:$J, 0)) -> 22 | F5: =INDEX(raw_menu_profitability!$D:$D, MATCH(C5, raw_menu_profitability!$J:$J, 0)) -> Spaghetti alla Carbonara | G5: =INDEX(raw_menu_profitability!$G:$G, MATCH(C5, raw_menu_profitability!$J:$J, 0)) -> 3.9925 | H5: =E5-G5 -> 18.0075 | I5: =H5/E5 -> 0.81852273 | J5: =IF(I5<$H$1, 1, 0) -> 0 | L5: margin is price - cost
A6: 1 | B6: 2 | C6: =(A6&", "& B6) -> 1, 2 | D6: =INDEX(raw_menu_profitability!$B:$B, MATCH(C6, raw_menu_profitability!$J:$J, 0)) -> Eataly Flatiron | E6: =INDEX(raw_menu_profitability!$F:$F, MATCH(C6, raw_menu_profitability!$J:$J, 0)) -> 24 | F6: =INDEX(raw_menu_profitability!$D:$D, MATCH(C6, raw_menu_profitability!$J:$J, 0)) -> Margherita Pizza | G6: =INDEX(raw_menu_profitability!$G:$G, MATCH(C6, raw_menu_profitability!$J:$J, 0)) -> 6.765 | H6: =E6-G6 -> 17.235 | I6: =H6/E6 -> 0.718125 | J6: =IF(I6<$H$1, 1, 0) -> 0 | L6: Target Margin is an assumption
A7: 1 | B7: 3 | C7: =(A7&", "& B7) -> 1, 3 | D7: =INDEX(raw_menu_profitability!$B:$B, MATCH(C7, raw_menu_profitability!$J:$J, 0)) -> Eataly Flatiron | E7: =INDEX(raw_menu_profitability!$F:$F, MATCH(C7, raw_menu_profitability!$J:$J, 0)) -> 25.5 | F7: =INDEX(raw_menu_profitability!$D:$D, MATCH(C7, raw_menu_profitability!$J:$J, 0)) -> Risotto alla Milanese | G7: =INDEX(raw_menu_profitability!$G:$G, MATCH(C7, raw_menu_profitability!$J:$J, 0)) -> 3.66 | H7: =E7-G7 -> 21.84 | I7: =H7/E7 -> 0.85647059 | J7: =IF(I7<$H$1, 1, 0) -> 0 | L7: Margin doesn't include overhead
A8: 1 | B8: 4 | C8: =(A8&", "& B8) -> 1, 4 | D8: =INDEX(raw_menu_profitability!$B:$B, MATCH(C8, raw_menu_profitability!$J:$J, 0)) -> Eataly Flatiron | E8: =INDEX(raw_menu_profitability!$F:$F, MATCH(C8, raw_menu_profitability!$J:$J, 0)) -> 21 | F8: =INDEX(raw_menu_profitability!$D:$D, MATCH(C8, raw_menu_profitability!$J:$J, 0)) -> Caprese Salad | G8: =INDEX(raw_menu_profitability!$G:$G, MATCH(C8, raw_menu_profitability!$J:$J, 0)) -> 6.99 | H8: =E8-G8 -> 14.01 | I8: =H8/E8 -> 0.66714286 | J8: =IF(I8<$H$1, 1, 0) -> 0
A9: 1 | B9: 5 | C9: =(A9&", "& B9) -> 1, 5 | D9: =INDEX(raw_menu_profitability!$B:$B, MATCH(C9, raw_menu_profitability!$J:$J, 0)) -> Eataly Flatiron | E9: =INDEX(raw_menu_profitability!$F:$F, MATCH(C9, raw_menu_profitability!$J:$J, 0)) -> 21 | F9: =INDEX(raw_menu_profitability!$D:$D, MATCH(C9, raw_menu_profitability!$J:$J, 0)) -> Prosciutto e Melone | G9: =INDEX(raw_menu_profitability!$G:$G, MATCH(C9, raw_menu_profitability!$J:$J, 0)) -> 6.95 | H9: =E9-G9 -> 14.05 | I9: =H9/E9 -> 0.66904762 | J9: =IF(I9<$H$1, 1, 0) -> 0 | L9: location_name | M9: dish_count | N9: flag_count | O9: pct_under_margin
A10: 1 | B10: 6 | C10: =(A10&", "& B10) -> 1, 6 | D10: =INDEX(raw_menu_profitability!$B:$B, MATCH(C10, raw_menu_profitability!$J:$J, 0)) -> Eataly Flatiron | E10: =INDEX(raw_menu_profitability!$F:$F, MATCH(C10, raw_menu_profitability!$J:$J, 0)) -> 23 | F10: =INDEX(raw_menu_profitability!$D:$D, MATCH(C10, raw_menu_profitability!$J:$J, 0)) -> Bucatini all'Amatriciana | G10: =INDEX(raw_menu_profitability!$G:$G, MATCH(C10, raw_menu_profitability!$J:$J, 0)) -> 4.7575 | H10: =E10-G10 -> 18.2425 | I10: =H10/E10 -> 0.79315217 | J10: =IF(I10<$H$1, 1, 0) -> 0 | L10: {=Lists!$A$2:$A$9} -> Eataly Flatiron | M10: =COUNTIF($D:$D,L10) -> 17 | N10: =SUMIFS($J$5:$J$135, $D$5:$D$135, "="& L10) -> 1 | O10: =N10/M10 -> 0.058823529
A11: 1 | B11: 7 | C11: =(A11&", "& B11) -> 1, 7 | D11: =INDEX(raw_menu_profitability!$B:$B, MATCH(C11, raw_menu_profitability!$J:$J, 0)) -> Eataly Flatiron | E11: =INDEX(raw_menu_profitability!$F:$F, MATCH(C11, raw_menu_profitability!$J:$J, 0)) -> 10.5 | F11: =INDEX(raw_menu_profitability!$D:$D, MATCH(C11, raw_menu_profitability!$J:$J, 0)) -> Tiramisu | G11: =INDEX(raw_menu_profitability!$G:$G, MATCH(C11, raw_menu_profitability!$J:$J, 0)) -> 2.895 | H11: =E11-G11 -> 7.605 | I11: =H11/E11 -> 0.72428571 | J11: =IF(I11<$H$1, 1, 0) -> 0 | L11: Eataly Downtown NYC | M11: =COUNTIF($D:$D,L11) -> 15 | N11: =SUMIFS($J$5:$J$135, $D$5:$D$135, "="& L11) -> 0 | O11: =N11/M11 -> 0
A12: 1 | B12: 8 | C12: =(A12&", "& B12) -> 1, 8 | D12: =INDEX(raw_menu_profitability!$B:$B, MATCH(C12, raw_menu_profitability!$J:$J, 0)) -> Eataly Flatiron | E12: =INDEX(raw_menu_profitability!$F:$F, MATCH(C12, raw_menu_profitability!$J:$J, 0)) -> 12.5 | F12: =INDEX(raw_menu_profitability!$D:$D, MATCH(C12, raw_menu_profitability!$J:$J, 0)) -> Focaccia Genovese | G12: =INDEX(raw_menu_profitability!$G:$G, MATCH(C12, raw_menu_profitability!$J:$J, 0)) -> 0.681667 | H12: =E12-G12 -> 11.818333 | I12: =H12/E12 -> 0.94546664 | J12: =IF(I12<$H$1, 1, 0) -> 0 | L12: Eataly Boston | M12: =COUNTIF($D:$D,L12) -> 14 | N12: =SUMIFS($J$5:$J$135, $D$5:$D$135, "="& L12) -> 1 | O12: =N12/M12 -> 0.071428571
A13: 1 | B13: 9 | C13: =(A13&", "& B13) -> 1, 9 | D13: =INDEX(raw_menu_profitability!$B:$B, MATCH(C13, raw_menu_profitability!$J:$J, 0)) -> Eataly Flatiron | E13: =INDEX(raw_menu_profitability!$F:$F, MATCH(C13, raw_menu_profitability!$J:$J, 0)) -> 49.5 | F13: =INDEX(raw_menu_profitability!$D:$D, MATCH(C13, raw_menu_profitability!$J:$J, 0)) -> Osso Buco | G13: =INDEX(raw_menu_profitability!$G:$G, MATCH(C13, raw_menu_profitability!$J:$J, 0)) -> 18.25 | H13: =E13-G13 -> 31.25 | I13: =H13/E13 -> 0.63131313 | J13: =IF(I13<$H$1, 1, 0) -> 1 | L13: Eataly Chicago | M13: =COUNTIF($D:$D,L13) -> 16 | N13: =SUMIFS($J$5:$J$135, $D$5:$D$135, "="& L13) -> 1 | O13: =N13/M13 -> 0.0625
A14: 1 | B14: 11 | C14: =(A14&", "& B14) -> 1, 11 | D14: =INDEX(raw_menu_profitability!$B:$B, MATCH(C14, raw_menu_profitability!$J:$J, 0)) -> Eataly Flatiron | E14: =INDEX(raw_menu_profitability!$F:$F, MATCH(C14, raw_menu_profitability!$J:$J, 0)) -> 21 | F14: =INDEX(raw_menu_profitability!$D:$D, MATCH(C14, raw_menu_profitability!$J:$J, 0)) -> Cacio e Pepe | G14: =INDEX(raw_menu_profitability!$G:$G, MATCH(C14, raw_menu_profitability!$J:$J, 0)) -> 1.975 | H14: =E14-G14 -> 19.025 | I14: =H14/E14 -> 0.90595238 | J14: =IF(I14<$H$1, 1, 0) -> 0 | L14: Eataly Los Angeles | M14: =COUNTIF($D:$D,L14) -> 15 | N14: =SUMIFS($J$5:$J$135, $D$5:$D$135, "="& L14) -> 1 | O14: =N14/M14 -> 0.066666667
A15: 1 | B15: 12 | C15: =(A15&", "& B15) -> 1, 12 | D15: =INDEX(raw_menu_profitability!$B:$B, MATCH(C15, raw_menu_profitability!$J:$J, 0)) -> Eataly Flatiron | E15: =INDEX(raw_menu_profitability!$F:$F, MATCH(C15, raw_menu_profitability!$J:$J, 0)) -> 22 | F15: =INDEX(raw_menu_profitability!$D:$D, MATCH(C15, raw_menu_profitability!$J:$J, 0)) -> Pesto alla Genovese | G15: =INDEX(raw_menu_profitability!$G:$G, MATCH(C15, raw_menu_profitability!$J:$J, 0)) -> 2.5825 | H15: =E15-G15 -> 19.4175 | I15: =H15/E15 -> 0.88261364 | J15: =IF(I15<$H$1, 1, 0) -> 0 | L15: Eataly Las Vegas | M15: =COUNTIF($D:$D,L15) -> 18 | N15: =SUMIFS($J$5:$J$135, $D$5:$D$135, "="& L15) -> 2 | O15: =N15/M15 -> 0.11111111
A16: 1 | B16: 13 | C16: =(A16&", "& B16) -> 1, 13 | D16: =INDEX(raw_menu_profitability!$B:$B, MATCH(C16, raw_menu_profitability!$J:$J, 0)) -> Eataly Flatiron | E16: =INDEX(raw_menu_profitability!$F:$F, MATCH(C16, raw_menu_profitability!$J:$J, 0)) -> 23 | F16: =INDEX(raw_menu_profitability!$D:$D, MATCH(C16, raw_menu_profitability!$J:$J, 0)) -> Quattro Formaggi Pizza | G16: =INDEX(raw_menu_profitability!$G:$G, MATCH(C16, raw_menu_profitability!$J:$J, 0)) -> 6.865 | H16: =E16-G16 -> 16.135 | I16: =H16/E16 -> 0.70152174 | J16: =IF(I16<$H$1, 1, 0) -> 0 | L16: Eataly Dallas | M16: =COUNTIF($D:$D,L16) -> 18 | N16: =SUMIFS($J$5:$J$135, $D$5:$D$135, "="& L16) -> 4 | O16: =N16/M16 -> 0.22222222
A17: 1 | B17: 14 | C17: =(A17&", "& B17) -> 1, 14 | D17: =INDEX(raw_menu_profitability!$B:$B, MATCH(C17, raw_menu_profitability!$J:$J, 0)) -> Eataly Flatiron | E17: =INDEX(raw_menu_profitability!$F:$F, MATCH(C17, raw_menu_profitability!$J:$J, 0)) -> 28 | F17: =INDEX(raw_menu_profitability!$D:$D, MATCH(C17, raw_menu_profitability!$J:$J, 0)) -> Porchetta | G17: =INDEX(raw_menu_profitability!$G:$G, MATCH(C17, raw_menu_profitability!$J:$J, 0)) -> 4.076667 | H17: =E17-G17 -> 23.923333 | I17: =H17/E17 -> 0.85440475 | J17: =IF(I17<$H$1, 1, 0) -> 0 | L17: Eataly San Jose | M17: =COUNTIF($D:$D,L17) -> 18 | N17: =SUMIFS($J$5:$J$135, $D$5:$D$135, "="& L17) -> 2 | O17: =N17/M17 -> 0.11111111
A18: 1 | B18: 15 | C18: =(A18&", "& B18) -> 1, 15 | D18: =INDEX(raw_menu_profitability!$B:$B, MATCH(C18, raw_menu_profitability!$J:$J, 0)) -> Eataly Flatiron | E18: =INDEX(raw_menu_profitability!$F:$F, MATCH(C18, raw_menu_profitability!$J:$J, 0)) -> 25 | F18: =INDEX(raw_menu_profitability!$D:$D, MATCH(C18, raw_menu_profitability!$J:$J, 0)) -> Pollo alla Griglia | G18: =INDEX(raw_menu_profitability!$G:$G, MATCH(C18, raw_menu_profitability!$J:$J, 0)) -> 2.715 | H18: =E18-G18 -> 22.285 | I18: =H18/E18 -> 0.8914 | J18: =IF(I18<$H$1, 1, 0) -> 0 | L18: total | M18: =SUM(M10:M17) -> 131 | N18: =SUM(N10:N17) -> 12
A19: 1 | B19: 16 | C19: =(A19&", "& B19) -> 1, 16 | D19: =INDEX(raw_menu_profitability!$B:$B, MATCH(C19, raw_menu_profitability!$J:$J, 0)) -> Eataly Flatiron | E19: =INDEX(raw_menu_profitability!$F:$F, MATCH(C19, raw_menu_profitability!$J:$J, 0)) -> 9 | F19: =INDEX(raw_menu_profitability!$D:$D, MATCH(C19, raw_menu_profitability!$J:$J, 0)) -> Cannoli | G19: =INDEX(raw_menu_profitability!$G:$G, MATCH(C19, raw_menu_profitability!$J:$J, 0)) -> 1.560833 | H19: =E19-G19 -> 7.439167 | I19: =H19/E19 -> 0.82657411 | J19: =IF(I19<$H$1, 1, 0) -> 0
A20: 1 | B20: 17 | C20: =(A20&", "& B20) -> 1, 17 | D20: =INDEX(raw_menu_profitability!$B:$B, MATCH(C20, raw_menu_profitability!$J:$J, 0)) -> Eataly Flatiron | E20: =INDEX(raw_menu_profitability!$F:$F, MATCH(C20, raw_menu_profitability!$J:$J, 0)) -> 8 | F20: =INDEX(raw_menu_profitability!$D:$D, MATCH(C20, raw_menu_profitability!$J:$J, 0)) -> Pistachio Gelato | G20: =INDEX(raw_menu_profitability!$G:$G, MATCH(C20, raw_menu_profitability!$J:$J, 0)) -> 1.40375 | H20: =E20-G20 -> 6.59625 | I20: =H20/E20 -> 0.82453125 | J20: =IF(I20<$H$1, 1, 0) -> 0
A21: 1 | B21: 18 | C21: =(A21&", "& B21) -> 1, 18 | D21: =INDEX(raw_menu_profitability!$B:$B, MATCH(C21, raw_menu_profitability!$J:$J, 0)) -> Eataly Flatiron | E21: =INDEX(raw_menu_profitability!$F:$F, MATCH(C21, raw_menu_profitability!$J:$J, 0)) -> 23.5 | F21: =INDEX(raw_menu_profitability!$D:$D, MATCH(C21, raw_menu_profitability!$J:$J, 0)) -> Insalata di Mare | G21: =INDEX(raw_menu_profitability!$G:$G, MATCH(C21, raw_menu_profitability!$J:$J, 0)) -> 5.93 | H21: =E21-G21 -> 17.57 | I21: =H21/E21 -> 0.74765957 | J21: =IF(I21<$H$1, 1, 0) -> 0
A22: 2 | B22: 1 | C22: =(A22&", "& B22) -> 2, 1 | D22: =INDEX(raw_menu_profitability!$B:$B, MATCH(C22, raw_menu_profitability!$J:$J, 0)) -> Eataly Downtown NYC | E22: =INDEX(raw_menu_profitability!$F:$F, MATCH(C22, raw_menu_profitability!$J:$J, 0)) -> 22 | F22: =INDEX(raw_menu_profitability!$D:$D, MATCH(C22, raw_menu_profitability!$J:$J, 0)) -> Spaghetti alla Carbonara | G22: =INDEX(raw_menu_profitability!$G:$G, MATCH(C22, raw_menu_profitability!$J:$J, 0)) -> 3.96 | H22: =E22-G22 -> 18.04 | I22: =H22/E22 -> 0.82 | J22: =IF(I22<$H$1, 1, 0) -> 0
A23: 2 | B23: 2 | C23: =(A23&", "& B23) -> 2, 2 | D23: =INDEX(raw_menu_profitability!$B:$B, MATCH(C23, raw_menu_profitability!$J:$J, 0)) -> Eataly Downtown NYC | E23: =INDEX(raw_menu_profitability!$F:$F, MATCH(C23, raw_menu_profitability!$J:$J, 0)) -> 24 | F23: =INDEX(raw_menu_profitability!$D:$D, MATCH(C23, raw_menu_profitability!$J:$J, 0)) -> Margherita Pizza | G23: =INDEX(raw_menu_profitability!$G:$G, MATCH(C23, raw_menu_profitability!$J:$J, 0)) -> 6.695 | H23: =E23-G23 -> 17.305 | I23: =H23/E23 -> 0.72104167 | J23: =IF(I23<$H$1, 1, 0) -> 0
A24: 2 | B24: 3 | C24: =(A24&", "& B24) -> 2, 3 | D24: =INDEX(raw_menu_profitability!$B:$B, MATCH(C24, raw_menu_profitability!$J:$J, 0)) -> Eataly Downtown NYC | E24: =INDEX(raw_menu_profitability!$F:$F, MATCH(C24, raw_menu_profitability!$J:$J, 0)) -> 25.5 | F24: =INDEX(raw_menu_profitability!$D:$D, MATCH(C24, raw_menu_profitability!$J:$J, 0)) -> Risotto alla Milanese | G24: =INDEX(raw_menu_profitability!$G:$G, MATCH(C24, raw_menu_profitability!$J:$J, 0)) -> 3.7125 | H24: =E24-G24 -> 21.7875 | I24: =H24/E24 -> 0.85441176 | J24: =IF(I24<$H$1, 1, 0) -> 0
A25: 2 | B25: 4 | C25: =(A25&", "& B25) -> 2, 4 | D25: =INDEX(raw_menu_profitability!$B:$B, MATCH(C25, raw_menu_profitability!$J:$J, 0)) -> Eataly Downtown NYC | E25: =INDEX(raw_menu_profitability!$F:$F, MATCH(C25, raw_menu_profitability!$J:$J, 0)) -> 21 | F25: =INDEX(raw_menu_profitability!$D:$D, MATCH(C25, raw_menu_profitability!$J:$J, 0)) -> Caprese Salad | G25: =INDEX(raw_menu_profitability!$G:$G, MATCH(C25, raw_menu_profitability!$J:$J, 0)) -> 6.89 | H25: =E25-G25 -> 14.11 | I25: =H25/E25 -> 0.67190476 | J25: =IF(I25<$H$1, 1, 0) -> 0
A26: 2 | B26: 6 | C26: =(A26&", "& B26) -> 2, 6 | D26: =INDEX(raw_menu_profitability!$B:$B, MATCH(C26, raw_menu_profitability!$J:$J, 0)) -> Eataly Downtown NYC | E26: =INDEX(raw_menu_profitability!$F:$F, MATCH(C26, raw_menu_profitability!$J:$J, 0)) -> 23 | F26: =INDEX(raw_menu_profitability!$D:$D, MATCH(C26, raw_menu_profitability!$J:$J, 0)) -> Bucatini all'Amatriciana | G26: =INDEX(raw_menu_profitability!$G:$G, MATCH(C26, raw_menu_profitability!$J:$J, 0)) -> 4.67 | H26: =E26-G26 -> 18.33 | I26: =H26/E26 -> 0.79695652 | J26: =IF(I26<$H$1, 1, 0) -> 0
A27: 2 | B27: 8 | C27: =(A27&", "& B27) -> 2, 8 | D27: =INDEX(raw_menu_profitability!$B:$B, MATCH(C27, raw_menu_profitability!$J:$J, 0)) -> Eataly Downtown NYC | E27: =INDEX(raw_menu_profitability!$F:$F, MATCH(C27, raw_menu_profitability!$J:$J, 0)) -> 12.5 | F27: =INDEX(raw_menu_profitability!$D:$D, MATCH(C27, raw_menu_profitability!$J:$J, 0)) -> Focaccia Genovese | G27: =INDEX(raw_menu_profitability!$G:$G, MATCH(C27, raw_menu_profitability!$J:$J, 0)) -> 0.661667 | H27: =E27-G27 -> 11.838333 | I27: =H27/E27 -> 0.94706664 | J27: =IF(I27<$H$1, 1, 0) -> 0
A28: 2 | B28: 10 | C28: =(A28&", "& B28) -> 2, 10 | D28: =INDEX(raw_menu_profitability!$B:$B, MATCH(C28, raw_menu_profitability!$J:$J, 0)) -> Eataly Downtown NYC | E28: =INDEX(raw_menu_profitability!$F:$F, MATCH(C28, raw_menu_profitability!$J:$J, 0)) -> 14 | F28: =INDEX(raw_menu_profitability!$D:$D, MATCH(C28, raw_menu_profitability!$J:$J, 0)) -> Panzanella | G28: =INDEX(raw_menu_profitability!$G:$G, MATCH(C28, raw_menu_profitability!$J:$J, 0)) -> 1.9475 | H28: =E28-G28 -> 12.0525 | I28: =H28/E28 -> 0.86089286 | J28: =IF(I28<$H$1, 1, 0) -> 0
A29: 2 | B29: 11 | C29: =(A29&", "& B29) -> 2, 11 | D29: =INDEX(raw_menu_profitability!$B:$B, MATCH(C29, raw_menu_profitability!$J:$J, 0)) -> Eataly Downtown NYC | E29: =INDEX(raw_menu_profitability!$F:$F, MATCH(C29, raw_menu_profitability!$J:$J, 0)) -> 21 | F29: =INDEX(raw_menu_profitability!$D:$D, MATCH(C29, raw_menu_profitability!$J:$J, 0)) -> Cacio e Pepe | G29: =INDEX(raw_menu_profitability!$G:$G, MATCH(C29, raw_menu_profitability!$J:$J, 0)) -> 1.9725 | H29: =E29-G29 -> 19.0275 | I29: =H29/E29 -> 0.90607143 | J29: =IF(I29<$H$1, 1, 0) -> 0
A30: 2 | B30: 12 | C30: =(A30&", "& B30) -> 2, 12 | D30: =INDEX(raw_menu_profitability!$B:$B, MATCH(C30, raw_menu_profitability!$J:$J, 0)) -> Eataly Downtown NYC | E30: =INDEX(raw_menu_profitability!$F:$F, MATCH(C30, raw_menu_profitability!$J:$J, 0)) -> 22 | F30: =INDEX(raw_menu_profitability!$D:$D, MATCH(C30, raw_menu_profitability!$J:$J, 0)) -> Pesto alla Genovese | G30: =INDEX(raw_menu_profitability!$G:$G, MATCH(C30, raw_menu_profitability!$J:$J, 0)) -> 2.525 | H30: =E30-G30 -> 19.475 | I30: =H30/E30 -> 0.88522727 | J30: =IF(I30<$H$1, 1, 0) -> 0
... A135: 8 | B135: 18 | C135: =(A135&", "& B135) -> 8, 18 | D135: =INDEX(raw_menu_profitability!$B:$B, MATCH(C135, raw_menu_profitability!$J:$J, 0)) -> Eataly San Jose | E135: =INDEX(raw_menu_profitability!$F:$F, MATCH(C135, raw_menu_profitability!$J:$J, 0)) -> 23 | F135: =INDEX(raw_menu_profitability!$D:$D, MATCH(C135, raw_menu_profitability!$J:$J, 0)) -> Insalata di Mare | G135: =INDEX(raw_menu_profitability!$G:$G, MATCH(C135, raw_menu_profitability!$J:$J, 0)) -> 6.285 | H135: =E135-G135 -> 16.715 | I135: =H135/E135 -> 0.72673913 | J135: =IF(I135<$H$1, 1, 0) -> 0

Sheet Menu_Performance
F1: ="Menu Performance" & " (" & Menu_Performance!$C$3 & ": " & TEXT(C5, "mmm yyyy") & " - " & TEXT(C6, "mmm yyyy") & ")" -> Menu Performance (Eataly Dallas: Feb 2025 - Sep 2026)
B2: NOTE: | C2: Dishes are compared to others within the selected time window and location
B3: location_name | C3: Eataly Dallas | H3: unconverted_ingredient_count | I3: =SUMIFS(raw_menu_engineering!K:K, raw_menu_engineering!A:A, ">="& $C$5, raw_menu_engineering!A:A, "<="& $C$6, raw_menu_engineering!B:B, $C$4) -> 0
B4: location_id | C4: =INDEX(Lists!$B:$B, MATCH(C3,Lists!$A:$A, 0)) -> 7 | E4: diff_tolerance | F4: 0.005 | G4: half a cent per month | J4: =IF(I3=0, "OK", "unconverted ingredient") -> OK | K4: pct_of_even_split | L4: 0.7
B5: start_month | C5: 45689 | E5: month_count | F5: =(YEAR(C6) - YEAR(C5)) * 12 + MONTH(C6) - MONTH(C5) + 1 -> 20 | H5: unconverted_recipe_count | I5: =SUMIFS(raw_location_month_performance!S:S, raw_location_month_performance!C:C, ">="& $C$5, raw_location_month_performance!C:C, "<="& $C$6, raw_location_month_performance!A:A, $C$4) -> 0 | J5: =IF(I5=0, "OK", "unconverted recipe") -> OK | K5: num_items_with_sales | L5: =COUNTIF($E$9:$E$26, ">0") -> 18
B6: end_month | C6: 46266 | D6: =IF(C6<C5, "End before Start", "") | E6: overall_status | F6: =IF(AND(E28=0,C5<=C6),"NO SALES",IF(C6<C5,"END BEFORE START",IF(AND(D31="PASS",E31="PASS",F31="PASS",G31="PASS"),IF(AND(J4="OK", J5="OK"),"PASS","FAIL"), "FAIL"))) -> PASS | K6: threshold | L6: =IF(L5=0,"-",(L4*(1/L5))) -> 0.038888889
K7: benchmark | L7: =IF(E28=0, "-", G28/E28) -> 13.48591
B8: recipe_id | C8: recipe_name | D8: revenue_dollars | E8: quantity_sold | F8: cost_dollars | G8: gross_profit_dollars | H8: margin_pct | I8: units_share | J8: popularity | K8: gross_profit_per_unit | L8: profitable? | M8: category | N8: rank
B9: 1 | C9: =INDEX(raw_menu_engineering!$E:$E, MATCH(B9, raw_menu_engineering!$D:$D, 0)) -> Spaghetti alla Carbonara | D9: =SUMIFS(raw_menu_engineering!F:F, raw_menu_engineering!A:A, ">="& $C$5, raw_menu_engineering!A:A, "<="& $C$6, raw_menu_engineering!B:B, $C$4, raw_menu_engineering!D:D,$B9) -> 51547 | E9: =SUMIFS(raw_menu_engineering!G:G, raw_menu_engineering!A:A, ">="& $C$5, raw_menu_engineering!A:A, "<="& $C$6, raw_menu_engineering!B:B, $C$4, raw_menu_engineering!D:D,$B9) -> 2713 | F9: =SUMIFS(raw_menu_engineering!I:I, raw_menu_engineering!A:A, ">="& $C$5, raw_menu_engineering!A:A, "<="& $C$6, raw_menu_engineering!B:B, $C$4, raw_menu_engineering!D:D,$B9) -> 10120.216 | G9: =IF(E9=0, "-", D9-F9) -> 41426.784 | H9: =IF(D9 = 0, "-", G9/D9) -> 0.80367012 | I9: =IF(E9=0, "-", E9/$E$28) -> 0.088273573 | J9: =IF(E9=0,"-",(IF(I9>=$L$6,1,0))) -> 1 | K9: =IF(E9=0, "-", G9/E9) -> 15.269732 | L9: =IF(E9=0, "-", IF(K9 >=$L$7, 1, 0)) -> 1 | M9: =IF(AND(J9=0,L9=0),"DOG",IF(AND(J9=1,L9=0),"PLOWHORSE",IF(AND(J9=0,L9=1),"PUZZLE",IF(AND(J9=1,L9=1),"STAR","-")))) -> STAR | N9: =IF(G9="-", "-", RANK(G9,$G$9:$G$26, 0)) -> 2
B10: 2 | C10: =INDEX(raw_menu_engineering!$E:$E, MATCH(B10, raw_menu_engineering!$D:$D, 0)) -> Margherita Pizza | D10: =SUMIFS(raw_menu_engineering!F:F, raw_menu_engineering!A:A, ">="& $C$5, raw_menu_engineering!A:A, "<="& $C$6, raw_menu_engineering!B:B, $C$4, raw_menu_engineering!D:D,$B10) -> 59367 | E10: =SUMIFS(raw_menu_engineering!G:G, raw_menu_engineering!A:A, ">="& $C$5, raw_menu_engineering!A:A, "<="& $C$6, raw_menu_engineering!B:B, $C$4, raw_menu_engineering!D:D,$B10) -> 2827 | F10: =SUMIFS(raw_menu_engineering!I:I, raw_menu_engineering!A:A, ">="& $C$5, raw_menu_engineering!A:A, "<="& $C$6, raw_menu_engineering!B:B, $C$4, raw_menu_engineering!D:D,$B10) -> 18653.535 | G10: =IF(E10=0, "-", D10-F10) -> 40713.465 | H10: =IF(D10 = 0, "-", G10/D10) -> 0.68579286 | I10: =IF(E10=0, "-", E10/$E$28) -> 0.09198282 | J10: =IF(E10=0,"-",(IF(I10>=$L$6,1,0))) -> 1 | K10: =IF(E10=0, "-", G10/E10) -> 14.40165 | L10: =IF(E10=0, "-", IF(K10 >=$L$7, 1, 0)) -> 1 | M10: =IF(AND(J10=0,L10=0),"DOG",IF(AND(J10=1,L10=0),"PLOWHORSE",IF(AND(J10=0,L10=1),"PUZZLE",IF(AND(J10=1,L10=1),"STAR","-")))) -> STAR | N10: =IF(G10="-", "-", RANK(G10,$G$9:$G$26, 0)) -> 3
B11: 3 | C11: =INDEX(raw_menu_engineering!$E:$E, MATCH(B11, raw_menu_engineering!$D:$D, 0)) -> Risotto alla Milanese | D11: =SUMIFS(raw_menu_engineering!F:F, raw_menu_engineering!A:A, ">="& $C$5, raw_menu_engineering!A:A, "<="& $C$6, raw_menu_engineering!B:B, $C$4, raw_menu_engineering!D:D,$B11) -> 25388 | E11: =SUMIFS(raw_menu_engineering!G:G, raw_menu_engineering!A:A, ">="& $C$5, raw_menu_engineering!A:A, "<="& $C$6, raw_menu_engineering!B:B, $C$4, raw_menu_engineering!D:D,$B11) -> 1154 | F11: =SUMIFS(raw_menu_engineering!I:I, raw_menu_engineering!A:A, ">="& $C$5, raw_menu_engineering!A:A, "<="& $C$6, raw_menu_engineering!B:B, $C$4, raw_menu_engineering!D:D,$B11) -> 3907.8237 | G11: =IF(E11=0, "-", D11-F11) -> 21480.176 | H11: =IF(D11 = 0, "-", G11/D11) -> 0.84607595 | I11: =IF(E11=0, "-", E11/$E$28) -> 0.037547992 | J11: =IF(E11=0,"-",(IF(I11>=$L$6,1,0))) -> 0 | K11: =IF(E11=0, "-", G11/E11) -> 18.613671 | L11: =IF(E11=0, "-", IF(K11 >=$L$7, 1, 0)) -> 1 | M11: =IF(AND(J11=0,L11=0),"DOG",IF(AND(J11=1,L11=0),"PLOWHORSE",IF(AND(J11=0,L11=1),"PUZZLE",IF(AND(J11=1,L11=1),"STAR","-")))) -> PUZZLE | N11: =IF(G11="-", "-", RANK(G11,$G$9:$G$26, 0)) -> 8
B12: 4 | C12: =INDEX(raw_menu_engineering!$E:$E, MATCH(B12, raw_menu_engineering!$D:$D, 0)) -> Caprese Salad | D12: =SUMIFS(raw_menu_engineering!F:F, raw_menu_engineering!A:A, ">="& $C$5, raw_menu_engineering!A:A, "<="& $C$6, raw_menu_engineering!B:B, $C$4, raw_menu_engineering!D:D,$B12) -> 33804 | E12: =SUMIFS(raw_menu_engineering!G:G, raw_menu_engineering!A:A, ">="& $C$5, raw_menu_engineering!A:A, "<="& $C$6, raw_menu_engineering!B:B, $C$4, raw_menu_engineering!D:D,$B12) -> 1878 | F12: =SUMIFS(raw_menu_engineering!I:I, raw_menu_engineering!A:A, ">="& $C$5, raw_menu_engineering!A:A, "<="& $C$6, raw_menu_engineering!B:B, $C$4, raw_menu_engineering!D:D,$B12) -> 13226.665 | G12: =IF(E12=0, "-", D12-F12) -> 20577.335 | H12: =IF(D12 = 0, "-", G12/D12) -> 0.60872486 | I12: =IF(E12=0, "-", E12/$E$28) -> 0.061104965 | J12: =IF(E12=0,"-",(IF(I12>=$L$6,1,0))) -> 1 | K12: =IF(E12=0, "-", G12/E12) -> 10.957047 | L12: =IF(E12=0, "-", IF(K12 >=$L$7, 1, 0)) -> 0 | M12: =IF(AND(J12=0,L12=0),"DOG",IF(AND(J12=1,L12=0),"PLOWHORSE",IF(AND(J12=0,L12=1),"PUZZLE",IF(AND(J12=1,L12=1),"STAR","-")))) -> PLOWHORSE | N12: =IF(G12="-", "-", RANK(G12,$G$9:$G$26, 0)) -> 9
B13: 5 | C13: =INDEX(raw_menu_engineering!$E:$E, MATCH(B13, raw_menu_engineering!$D:$D, 0)) -> Prosciutto e Melone | D13: =SUMIFS(raw_menu_engineering!F:F, raw_menu_engineering!A:A, ">="& $C$5, raw_menu_engineering!A:A, "<="& $C$6, raw_menu_engineering!B:B, $C$4, raw_menu_engineering!D:D,$B13) -> 18204 | E13: =SUMIFS(raw_menu_engineering!G:G, raw_menu_engineering!A:A, ">="& $C$5, raw_menu_engineering!A:A, "<="& $C$6, raw_menu_engineering!B:B, $C$4, raw_menu_engineering!D:D,$B13) -> 984 | F13: =SUMIFS(raw_menu_engineering!I:I, raw_menu_engineering!A:A, ">="& $C$5, raw_menu_engineering!A:A, "<="& $C$6, raw_menu_engineering!B:B, $C$4, raw_menu_engineering!D:D,$B13) -> 6178.4782 | G13: =IF(E13=0, "-", D13-F13) -> 12025.522 | H13: =IF(D13 = 0, "-", G13/D13) -> 0.66059777 | I13: =IF(E13=0, "-", E13/$E$28) -> 0.032016659 | J13: =IF(E13=0,"-",(IF(I13>=$L$6,1,0))) -> 0 | K13: =IF(E13=0, "-", G13/E13) -> 12.221059 | L13: =IF(E13=0, "-", IF(K13 >=$L$7, 1, 0)) -> 0 | M13: =IF(AND(J13=0,L13=0),"DOG",IF(AND(J13=1,L13=0),"PLOWHORSE",IF(AND(J13=0,L13=1),"PUZZLE",IF(AND(J13=1,L13=1),"STAR","-")))) -> DOG | N13: =IF(G13="-", "-", RANK(G13,$G$9:$G$26, 0)) -> 15
B14: 6 | C14: =INDEX(raw_menu_engineering!$E:$E, MATCH(B14, raw_menu_engineering!$D:$D, 0)) -> Bucatini all'Amatriciana | D14: =SUMIFS(raw_menu_engineering!F:F, raw_menu_engineering!A:A, ">="& $C$5, raw_menu_engineering!A:A, "<="& $C$6, raw_menu_engineering!B:B, $C$4, raw_menu_engineering!D:D,$B14) -> 34066.5 | E14: =SUMIFS(raw_menu_engineering!G:G, raw_menu_engineering!A:A, ">="& $C$5, raw_menu_engineering!A:A, "<="& $C$6, raw_menu_engineering!B:B, $C$4, raw_menu_engineering!D:D,$B14) -> 1747 | F14: =SUMIFS(raw_menu_engineering!I:I, raw_menu_engineering!A:A, ">="& $C$5, raw_menu_engineering!A:A, "<="& $C$6, raw_menu_engineering!B:B, $C$4, raw_menu_engineering!D:D,$B14) -> 7855.6227 | G14: =IF(E14=0, "-", D14-F14) -> 26210.877 | H14: =IF(D14 = 0, "-", G14/D14) -> 0.76940329 | I14: =IF(E14=0, "-", E14/$E$28) -> 0.056842585 | J14: =IF(E14=0,"-",(IF(I14>=$L$6,1,0))) -> 1 | K14: =IF(E14=0, "-", G14/E14) -> 15.003364 | L14: =IF(E14=0, "-", IF(K14 >=$L$7, 1, 0)) -> 1 | M14: =IF(AND(J14=0,L14=0),"DOG",IF(AND(J14=1,L14=0),"PLOWHORSE",IF(AND(J14=0,L14=1),"PUZZLE",IF(AND(J14=1,L14=1),"STAR","-")))) -> STAR | N14: =IF(G14="-", "-", RANK(G14,$G$9:$G$26, 0)) -> 7
B15: 7 | C15: =INDEX(raw_menu_engineering!$E:$E, MATCH(B15, raw_menu_engineering!$D:$D, 0)) -> Tiramisu | D15: =SUMIFS(raw_menu_engineering!F:F, raw_menu_engineering!A:A, ">="& $C$5, raw_menu_engineering!A:A, "<="& $C$6, raw_menu_engineering!B:B, $C$4, raw_menu_engineering!D:D,$B15) -> 22212 | E15: =SUMIFS(raw_menu_engineering!G:G, raw_menu_engineering!A:A, ">="& $C$5, raw_menu_engineering!A:A, "<="& $C$6, raw_menu_engineering!B:B, $C$4, raw_menu_engineering!D:D,$B15) -> 2468 | F15: =SUMIFS(raw_menu_engineering!I:I, raw_menu_engineering!A:A, ">="& $C$5, raw_menu_engineering!A:A, "<="& $C$6, raw_menu_engineering!B:B, $C$4, raw_menu_engineering!D:D,$B15) -> 6905.1361 | G15: =IF(E15=0, "-", D15-F15) -> 15306.864 | H15: =IF(D15 = 0, "-", G15/D15) -> 0.68912587 | I15: =IF(E15=0, "-", E15/$E$28) -> 0.080301946 | J15: =IF(E15=0,"-",(IF(I15>=$L$6,1,0))) -> 1 | K15: =IF(E15=0, "-", G15/E15) -> 6.2021329 | L15: =IF(E15=0, "-", IF(K15 >=$L$7, 1, 0)) -> 0 | M15: =IF(AND(J15=0,L15=0),"DOG",IF(AND(J15=1,L15=0),"PLOWHORSE",IF(AND(J15=0,L15=1),"PUZZLE",IF(AND(J15=1,L15=1),"STAR","-")))) -> PLOWHORSE | N15: =IF(G15="-", "-", RANK(G15,$G$9:$G$26, 0)) -> 12
B16: 8 | C16: =INDEX(raw_menu_engineering!$E:$E, MATCH(B16, raw_menu_engineering!$D:$D, 0)) -> Focaccia Genovese | D16: =SUMIFS(raw_menu_engineering!F:F, raw_menu_engineering!A:A, ">="& $C$5, raw_menu_engineering!A:A, "<="& $C$6, raw_menu_engineering!B:B, $C$4, raw_menu_engineering!D:D,$B16) -> 15609 | E16: =SUMIFS(raw_menu_engineering!G:G, raw_menu_engineering!A:A, ">="& $C$5, raw_menu_engineering!A:A, "<="& $C$6, raw_menu_engineering!B:B, $C$4, raw_menu_engineering!D:D,$B16) -> 1419 | F16: =SUMIFS(raw_menu_engineering!I:I, raw_menu_engineering!A:A, ">="& $C$5, raw_menu_engineering!A:A, "<="& $C$6, raw_menu_engineering!B:B, $C$4, raw_menu_engineering!D:D,$B16) -> 947.5158 | G16: =IF(E16=0, "-", D16-F16) -> 14661.484 | H16: =IF(D16 = 0, "-", G16/D16) -> 0.93929683 | I16: =IF(E16=0, "-", E16/$E$28) -> 0.046170365 | J16: =IF(E16=0,"-",(IF(I16>=$L$6,1,0))) -> 1 | K16: =IF(E16=0, "-", G16/E16) -> 10.332265 | L16: =IF(E16=0, "-", IF(K16 >=$L$7, 1, 0)) -> 0 | M16: =IF(AND(J16=0,L16=0),"DOG",IF(AND(J16=1,L16=0),"PLOWHORSE",IF(AND(J16=0,L16=1),"PUZZLE",IF(AND(J16=1,L16=1),"STAR","-")))) -> PLOWHORSE | N16: =IF(G16="-", "-", RANK(G16,$G$9:$G$26, 0)) -> 13
B17: 9 | C17: =INDEX(raw_menu_engineering!$E:$E, MATCH(B17, raw_menu_engineering!$D:$D, 0)) -> Osso Buco | D17: =SUMIFS(raw_menu_engineering!F:F, raw_menu_engineering!A:A, ">="& $C$5, raw_menu_engineering!A:A, "<="& $C$6, raw_menu_engineering!B:B, $C$4, raw_menu_engineering!D:D,$B17) -> 27778 | E17: =SUMIFS(raw_menu_engineering!G:G, raw_menu_engineering!A:A, ">="& $C$5, raw_menu_engineering!A:A, "<="& $C$6, raw_menu_engineering!B:B, $C$4, raw_menu_engineering!D:D,$B17) -> 646 | F17: =SUMIFS(raw_menu_engineering!I:I, raw_menu_engineering!A:A, ">="& $C$5, raw_menu_engineering!A:A, "<="& $C$6, raw_menu_engineering!B:B, $C$4, raw_menu_engineering!D:D,$B17) -> 9989.5899 | G17: =IF(E17=0, "-", D17-F17) -> 17788.41 | H17: =IF(D17 = 0, "-", G17/D17) -> 0.64037764 | I17: =IF(E17=0, "-", E17/$E$28) -> 0.021019067 | J17: =IF(E17=0,"-",(IF(I17>=$L$6,1,0))) -> 0 | K17: =IF(E17=0, "-", G17/E17) -> 27.536239 | L17: =IF(E17=0, "-", IF(K17 >=$L$7, 1, 0)) -> 1 | M17: =IF(AND(J17=0,L17=0),"DOG",IF(AND(J17=1,L17=0),"PLOWHORSE",IF(AND(J17=0,L17=1),"PUZZLE",IF(AND(J17=1,L17=1),"STAR","-")))) -> PUZZLE | N17: =IF(G17="-", "-", RANK(G17,$G$9:$G$26, 0)) -> 11
B18: 10 | C18: =INDEX(raw_menu_engineering!$E:$E, MATCH(B18, raw_menu_engineering!$D:$D, 0)) -> Panzanella | D18: =SUMIFS(raw_menu_engineering!F:F, raw_menu_engineering!A:A, ">="& $C$5, raw_menu_engineering!A:A, "<="& $C$6, raw_menu_engineering!B:B, $C$4, raw_menu_engineering!D:D,$B18) -> 12888 | E18: =SUMIFS(raw_menu_engineering!G:G, raw_menu_engineering!A:A, ">="& $C$5, raw_menu_engineering!A:A, "<="& $C$6, raw_menu_engineering!B:B, $C$4, raw_menu_engineering!D:D,$B18) -> 1074 | F18: =SUMIFS(raw_menu_engineering!I:I, raw_menu_engineering!A:A, ">="& $C$5, raw_menu_engineering!A:A, "<="& $C$6, raw_menu_engineering!B:B, $C$4, raw_menu_engineering!D:D,$B18) -> 2209.049 | G18: =IF(E18=0, "-", D18-F18) -> 10678.951 | H18: =IF(D18 = 0, "-", G18/D18) -> 0.82859645 | I18: =IF(E18=0, "-", E18/$E$28) -> 0.034945012 | J18: =IF(E18=0,"-",(IF(I18>=$L$6,1,0))) -> 0 | K18: =IF(E18=0, "-", G18/E18) -> 9.9431574 | L18: =IF(E18=0, "-", IF(K18 >=$L$7, 1, 0)) -> 0 | M18: =IF(AND(J18=0,L18=0),"DOG",IF(AND(J18=1,L18=0),"PLOWHORSE",IF(AND(J18=0,L18=1),"PUZZLE",IF(AND(J18=1,L18=1),"STAR","-")))) -> DOG | N18: =IF(G18="-", "-", RANK(G18,$G$9:$G$26, 0)) -> 16
B19: 11 | C19: =INDEX(raw_menu_engineering!$E:$E, MATCH(B19, raw_menu_engineering!$D:$D, 0)) -> Cacio e Pepe | D19: =SUMIFS(raw_menu_engineering!F:F, raw_menu_engineering!A:A, ">="& $C$5, raw_menu_engineering!A:A, "<="& $C$6, raw_menu_engineering!B:B, $C$4, raw_menu_engineering!D:D,$B19) -> 39812 | E19: =SUMIFS(raw_menu_engineering!G:G, raw_menu_engineering!A:A, ">="& $C$5, raw_menu_engineering!A:A, "<="& $C$6, raw_menu_engineering!B:B, $C$4, raw_menu_engineering!D:D,$B19) -> 2152 | F19: =SUMIFS(raw_menu_engineering!I:I, raw_menu_engineering!A:A, ">="& $C$5, raw_menu_engineering!A:A, "<="& $C$6, raw_menu_engineering!B:B, $C$4, raw_menu_engineering!D:D,$B19) -> 4398.8294 | G19: =IF(E19=0, "-", D19-F19) -> 35413.171 | H19: =IF(D19 = 0, "-", G19/D19) -> 0.88950996 | I19: =IF(E19=0, "-", E19/$E$28) -> 0.070020173 | J19: =IF(E19=0,"-",(IF(I19>=$L$6,1,0))) -> 1 | K19: =IF(E19=0, "-", G19/E19) -> 16.455934 | L19: =IF(E19=0, "-", IF(K19 >=$L$7, 1, 0)) -> 1 | M19: =IF(AND(J19=0,L19=0),"DOG",IF(AND(J19=1,L19=0),"PLOWHORSE",IF(AND(J19=0,L19=1),"PUZZLE",IF(AND(J19=1,L19=1),"STAR","-")))) -> STAR | N19: =IF(G19="-", "-", RANK(G19,$G$9:$G$26, 0)) -> 4
B20: 12 | C20: =INDEX(raw_menu_engineering!$E:$E, MATCH(B20, raw_menu_engineering!$D:$D, 0)) -> Pesto alla Genovese | D20: =SUMIFS(raw_menu_engineering!F:F, raw_menu_engineering!A:A, ">="& $C$5, raw_menu_engineering!A:A, "<="& $C$6, raw_menu_engineering!B:B, $C$4, raw_menu_engineering!D:D,$B20) -> 23389 | E20: =SUMIFS(raw_menu_engineering!G:G, raw_menu_engineering!A:A, ">="& $C$5, raw_menu_engineering!A:A, "<="& $C$6, raw_menu_engineering!B:B, $C$4, raw_menu_engineering!D:D,$B20) -> 1231 | F20: =SUMIFS(raw_menu_engineering!I:I, raw_menu_engineering!A:A, ">="& $C$5, raw_menu_engineering!A:A, "<="& $C$6, raw_menu_engineering!B:B, $C$4, raw_menu_engineering!D:D,$B20) -> 3147.208 | G20: =IF(E20=0, "-", D20-F20) -> 20241.792 | H20: =IF(D20 = 0, "-", G20/D20) -> 0.86544068 | I20: =IF(E20=0, "-", E20/$E$28) -> 0.040053361 | J20: =IF(E20=0,"-",(IF(I20>=$L$6,1,0))) -> 1 | K20: =IF(E20=0, "-", G20/E20) -> 16.443373 | L20: =IF(E20=0, "-", IF(K20 >=$L$7, 1, 0)) -> 1 | M20: =IF(AND(J20=0,L20=0),"DOG",IF(AND(J20=1,L20=0),"PLOWHORSE",IF(AND(J20=0,L20=1),"PUZZLE",IF(AND(J20=1,L20=1),"STAR","-")))) -> STAR | N20: =IF(G20="-", "-", RANK(G20,$G$9:$G$26, 0)) -> 10
... B26: 18 | C26: =INDEX(raw_menu_engineering!$E:$E, MATCH(B26, raw_menu_engineering!$D:$D, 0)) -> Insalata di Mare | D26: =SUMIFS(raw_menu_engineering!F:F, raw_menu_engineering!A:A, ">="& $C$5, raw_menu_engineering!A:A, "<="& $C$6, raw_menu_engineering!B:B, $C$4, raw_menu_engineering!D:D,$B26) -> 17650.5 | E26: =SUMIFS(raw_menu_engineering!G:G, raw_menu_engineering!A:A, ">="& $C$5, raw_menu_engineering!A:A, "<="& $C$6, raw_menu_engineering!B:B, $C$4, raw_menu_engineering!D:D,$B26) -> 861 | F26: =SUMIFS(raw_menu_engineering!I:I, raw_menu_engineering!A:A, ">="& $C$5, raw_menu_engineering!A:A, "<="& $C$6, raw_menu_engineering!B:B, $C$4, raw_menu_engineering!D:D,$B26) -> 5046.5944 | G26: =IF(E26=0, "-", D26-F26) -> 12603.906 | H26: =IF(D26 = 0, "-", G26/D26) -> 0.71408207 | I26: =IF(E26=0, "-", E26/$E$28) -> 0.028014577 | J26: =IF(E26=0,"-",(IF(I26>=$L$6,1,0))) -> 0 | K26: =IF(E26=0, "-", G26/E26) -> 14.638682 | L26: =IF(E26=0, "-", IF(K26 >=$L$7, 1, 0)) -> 1 | M26: =IF(AND(J26=0,L26=0),"DOG",IF(AND(J26=1,L26=0),"PLOWHORSE",IF(AND(J26=0,L26=1),"PUZZLE",IF(AND(J26=1,L26=1),"STAR","-")))) -> PUZZLE | N26: =IF(G26="-", "-", RANK(G26,$G$9:$G$26, 0)) -> 14
I27: pop_count | J27: =IF(L5=0, "-", COUNTIF(J9:J26, "=1")) -> 13 | K27: profitable_count | L27: =IF(E28=0, "-", COUNTIF(L9:L26, "=1")) -> 10
C28: total | D28: =SUM(D9:D26) -> 538065 | E28: =SUM(E9:E26) -> 30734 | F28: =SUM(F9:F26) -> 123589.05 | G28: =SUM(G9:G26) -> 414475.95 | H28: =IF(G28 = 0, "-", G28/D28) -> 0.77030833
C29: SUMIFS_total | D29: =SUMIFS(raw_location_month_performance!D:D, raw_location_month_performance!C:C, ">="& $C$5, raw_location_month_performance!C:C, "<="& $C$6, raw_location_month_performance!A:A, $C$4) -> 538065 | E29: =SUMIFS(raw_menu_engineering!G:G, raw_menu_engineering!A:A, ">="& $C$5, raw_menu_engineering!A:A, "<="& $C$6, raw_menu_engineering!B:B, $C$4) -> 30734 | F29: =SUMIFS(raw_location_month_performance!J:J, raw_location_month_performance!C:C, ">="& $C$5, raw_location_month_performance!C:C, "<="& $C$6, raw_location_month_performance!A:A, $C$4) -> 123589.04 | G29: =D29-F29 -> 414475.96 | H29: =IF(G29=0, "-", G29/D29) -> 0.77030835 | I29: top_grossing | J29: {=IF($F$6<>"PASS","-",_xlfn._xlws.FILTER($C$9:$C$26,N9:N26=MIN(N9:N26)))} -> Pollo alla Griglia | L29: least_grossing | M29: {=IF(F6<>"PASS", "-", _xlfn._xlws.FILTER($C$9:$C$26, N9:N26=MAX(N9:N26), "NONE"))} -> Cannoli
C30: Difference | D30: =D28-D29 -> 0 | E30: =E28-E29 -> 0 | F30: =F28-F29 -> 0.0084588702 | G30: =G28-G29 -> -0.0084588702 | H30: =IF(AND(H28="-", H29="-"), "-", H28-H29) -> -1.5720908e-08
C31: status | D31: =IF(E28=0, "NO SALES", IF(AND(D30>= -($F$5*$F$4), D30<= ($F$5*$F$4)), "PASS", "FAIL")) -> PASS | E31: =IF(E28=0, "NO SALES", IF(E28=E29, "PASS", "FAIL")) -> PASS | F31: =IF(E28=0, "NO SALES", IF(AND(F30>= -($F$5*$F$4), F30<= ($F$5*$F$4)), "PASS", "FAIL")) -> PASS | G31: =IF(E28=0, "NO SALES", IF(AND(G30>= -($F$5*$F$4), G30<= ($F$5*$F$4)), "PASS", "FAIL")) -> PASS
C33: STAR | D33: PUZZLE | E33: PLOWHORSE | F33: DOG | G33: no_sales | H33: total
B34: count | C34: =COUNTIF($M$9:$M$26, "STAR") -> 7 | D34: =COUNTIF($M$9:$M$26, "PUZZLE") -> 3 | E34: =COUNTIF($M$9:$M$26, "PLOWHORSE") -> 6 | F34: =COUNTIF($M$9:$M$26, "DOG") -> 2 | G34: =COUNTIF($M$9:$M$26, "-") -> 0 | H34: =SUM(C34:G34) -> 18
B35: revenue | C35: =SUMIFS($D$9:$D$26,$M$9:$M$26, "STAR") -> 297921.5 | D35: =SUMIFS($D$9:$D$26,$M$9:$M$26,"PUZZLE") -> 70816.5 | E35: =SUMIFS($D$9:$D$26,$M$9:$M$26, "PLOWHORSE") -> 138235 | F35: =SUMIFS($D$9:$D$26,$M$9:$M$26, "DOG") -> 31092 | G35: =SUMIFS($D$9:$D$26,$M$9:$M$26, "-") -> 0 | H35: =SUM(C35:G35) -> 538065 | I35: =IF(AND(H35-D28 >=-F4*F5, H35-D28 <=F4*F5), "PASS", "FAIL") -> PASS
B36: revenue_share_of_total | C36: =C35/$H$35 -> 0.55369054 | D36: =D35/$H$35 -> 0.13161328 | E36: =E35/$H$35 -> 0.25691134 | F36: =F35/$H$35 -> 0.05778484 | G36: =G35/$H$35 -> 0 | H36: =SUM(C36:G36) -> 1
B37: gross_profit | C37: =SUMIFS($G$9:$G$26,$M$9:$M$26, "STAR") -> 241968.78 | D37: =SUMIFS($G$9:$G$26,$M$9:$M$26, "PUZZLE") -> 51872.492 | E37: =SUMIFS($G$9:$G$26,$M$9:$M$26, "PLOWHORSE") -> 97930.209 | F37: =SUMIFS($G$9:$G$26,$M$9:$M$26, "DOG") -> 22704.473 | G37: =SUMIFS($G$9:$G$26,$M$9:$M$26, "-") -> 0 | H37: =SUM(C37:G37) -> 414475.95 | I37: =IF(AND(H37-G28 >=-F4*F5, H37-G28 <=F4*F5), "PASS", "FAIL") -> PASS
B38: profit_share_of_total | C38: =C37/$H$37 -> 0.58379449 | D38: =D37/$H$37 -> 0.12515199 | E38: =E37/$H$37 -> 0.23627477 | F38: =F37/$H$37 -> 0.054778746 | G38: =G37/$H$37 -> 0 | H38: =SUM(C38:G38) -> 1
B39: DISHES | C39: {=_xlfn._xlws.FILTER($C$9:$C$26, $M$9:$M$26="STAR", "NO STAR DISHES")} -> Spaghetti alla Carbonara | D39: {=_xlfn._xlws.FILTER(C9:C26, M9:M26="PUZZLE", "NO PUZZLE DISHES")} -> Risotto alla Milanese | E39: {=_xlfn._xlws.FILTER(C9:C26, M9:M26="PLOWHORSE", "NO PLOWHORSE DISHES")} -> Caprese Salad | F39: {=_xlfn._xlws.FILTER(C9:C26, M9:M26="DOG", "NO DOG DISHES")} -> Prosciutto e Melone | G39: {=_xlfn._xlws.FILTER(C9:C26, M9:M26="-", "ALL DISHES HAVE SALES")} -> ALL DISHES HAVE SALES
C40: Margherita Pizza | D40: Osso Buco | E40: Tiramisu | F40: Panzanella
C41: Bucatini all'Amatriciana | D41: Insalata di Mare | E41: Focaccia Genovese
C42: Cacio e Pepe | E42: Quattro Formaggi Pizza
C43: Pesto alla Genovese | E43: Cannoli
C44: Porchetta | E44: Pistachio Gelato
C45: Pollo alla Griglia
I49: chart_x | J49: chart_y | K49: chart_label | L49: chart_threshold_x | M49: chart_threshold_y
...

Sheet Ingredient_Cost

Sheet KPI_Reporting

Sheet Export_Log
B2: Export Date: 10/19/2026 | D2: Records: 2/1/25 to but not including 10/1/26
B3: Export | C3: Source | D3: Filter | E3: Rows | F3: Control Total | G3: MySQL | H3: CSV | I3: Difference
B4: menu_profitability_by_location.csv | C4: menu_profitability_by_location | D4: - | E4: 131 | F4: sum of menu_prices | G4: =RPM!M3 -> 0 | H4: =raw_menu_profitability!L3 -> 2692 | I4: =G4-H4 -> -2692
B5: menu_engineering.csv | C5: menu_engineering | D5: month window above | E5: 2637 | F5: sum of revenue_dollars | G5: 6238295.5 | H5: =raw_menu_engineering!N3 -> 6238295.5 | I5: =G5-H5 -> 0
B6: location_price_variance.csv | C6: location_price_variance | D6: month window above | E6: 8015 | F6: sum of purchase_dollars | G6: 1577342.2 | H6: =raw_location_price_variance!N3 -> 1577342.2 | I6: =G6-H6 -> 0
B7: location_monthly_performance.csv | C7: location_monthly_performance | D7: month window above | E7: 160 | F7: sum of sales_dollars | G7: 6238295.5 | H7: =raw_location_month_performance!D164 -> 6238295.5 | I7: =G7-H7 -> 0

Sheet raw_menu_profitability
A1: location_id | B1: location_name | C1: recipe_id | D1: recipe_name | E1: recipe_status | F1: menu_price | G1: cost_per_serving | H1: gross_profit_per_unit | I1: profit_margin_pct | J1: Helper
A2: 1 | B2: Eataly Flatiron | C2: 1 | D2: Spaghetti alla Carbonara | E2: ACTIVE | F2: 22 | G2: 3.9925 | H2: 18.0075 | I2: 0.81852273 | J2: =(A2&", "& C2) -> 1, 1
A3: 1 | B3: Eataly Flatiron | C3: 2 | D3: Margherita Pizza | E3: ACTIVE | F3: 24 | G3: 6.765 | H3: 17.235 | I3: 0.718125 | J3: =(A3&", "& C3) -> 1, 2 | K3: check_sum | L3: =SUM(F:F) -> 2692
A4: 1 | B4: Eataly Flatiron | C4: 3 | D4: Risotto alla Milanese | E4: ACTIVE | F4: 25.5 | G4: 3.66 | H4: 21.84 | I4: 0.85647059 | J4: =(A4&", "& C4) -> 1, 3
A5: 1 | B5: Eataly Flatiron | C5: 4 | D5: Caprese Salad | E5: ACTIVE | F5: 21 | G5: 6.99 | H5: 14.01 | I5: 0.66714286 | J5: =(A5&", "& C5) -> 1, 4
A6: 1 | B6: Eataly Flatiron | C6: 5 | D6: Prosciutto e Melone | E6: ACTIVE | F6: 21 | G6: 6.95 | H6: 14.05 | I6: 0.66904762 | J6: =(A6&", "& C6) -> 1, 5
A7: 1 | B7: Eataly Flatiron | C7: 6 | D7: Bucatini all'Amatriciana | E7: ACTIVE | F7: 23 | G7: 4.7575 | H7: 18.2425 | I7: 0.79315217 | J7: =(A7&", "& C7) -> 1, 6
A8: 1 | B8: Eataly Flatiron | C8: 7 | D8: Tiramisu | E8: ACTIVE | F8: 10.5 | G8: 2.895 | H8: 7.605 | I8: 0.72428571 | J8: =(A8&", "& C8) -> 1, 7
A9: 1 | B9: Eataly Flatiron | C9: 8 | D9: Focaccia Genovese | E9: ACTIVE | F9: 12.5 | G9: 0.681667 | H9: 11.818333 | I9: 0.94546664 | J9: =(A9&", "& C9) -> 1, 8
A10: 1 | B10: Eataly Flatiron | C10: 9 | D10: Osso Buco | E10: ACTIVE | F10: 49.5 | G10: 18.25 | H10: 31.25 | I10: 0.63131313 | J10: =(A10&", "& C10) -> 1, 9
A11: 1 | B11: Eataly Flatiron | C11: 11 | D11: Cacio e Pepe | E11: ACTIVE | F11: 21 | G11: 1.975 | H11: 19.025 | I11: 0.90595238 | J11: =(A11&", "& C11) -> 1, 11
A12: 1 | B12: Eataly Flatiron | C12: 12 | D12: Pesto alla Genovese | E12: ACTIVE | F12: 22 | G12: 2.5825 | H12: 19.4175 | I12: 0.88261364 | J12: =(A12&", "& C12) -> 1, 12
A13: 1 | B13: Eataly Flatiron | C13: 13 | D13: Quattro Formaggi Pizza | E13: ACTIVE | F13: 23 | G13: 6.865 | H13: 16.135 | I13: 0.70152174 | J13: =(A13&", "& C13) -> 1, 13
A14: 1 | B14: Eataly Flatiron | C14: 14 | D14: Porchetta | E14: ACTIVE | F14: 28 | G14: 4.076667 | H14: 23.923333 | I14: 0.85440475 | J14: =(A14&", "& C14) -> 1, 14
A15: 1 | B15: Eataly Flatiron | C15: 15 | D15: Pollo alla Griglia | E15: ACTIVE | F15: 25 | G15: 2.715 | H15: 22.285 | I15: 0.8914 | J15: =(A15&", "& C15) -> 1, 15
... A132: 8 | B132: Eataly San Jose | C132: 18 | D132: Insalata di Mare | E132: ACTIVE | F132: 23 | G132: 6.285 | H132: 16.715 | I132: 0.72673913 | J132: =(A132&", "& C132) -> 8, 18

Sheet raw_menu_engineering
A1: month_start | B1: location_id | C1: location_name | D1: recipe_id | E1: recipe_name | F1: revenue_dollars | G1: quantity_sold | H1: cost_per_item | I1: cost_dollars | J1: gross_profit_dollars | K1: has_unconverted_ingredient | L1: Helper
A2: 45689 | B2: 1 | C2: Eataly Flatiron | D2: 1 | E2: Spaghetti alla Carbonara | F2: 3872 | G2: 176 | H2: 3.7963062 | I2: 668.14989 | J2: 3203.8501 | K2: 0 | L2: =(A2& ", "& B2& ", "& D2) -> 45689, 1, 1 | N2: Sum of revenue_dollars
A3: 45689 | B3: 1 | C3: Eataly Flatiron | D3: 2 | E3: Margherita Pizza | F3: 4824 | G3: 201 | H3: 6.6085384 | I3: 1328.3162 | J3: 3495.6838 | K3: 0 | L3: =(A3& ", "& B3& ", "& D3) -> 45689, 1, 2 | N3: =SUM(F:F) -> 6238295.5
A4: 45689 | B4: 1 | C4: Eataly Flatiron | D4: 3 | E4: Risotto alla Milanese | F4: 3493.5 | G4: 137 | H4: 3.4561764 | I4: 473.49616 | J4: 3020.0038 | K4: 0 | L4: =(A4& ", "& B4& ", "& D4) -> 45689, 1, 3
A5: 45689 | B5: 1 | C5: Eataly Flatiron | D5: 4 | E5: Caprese Salad | F5: 2688 | G5: 128 | H5: 7.2041033 | I5: 922.12523 | J5: 1765.8748 | K5: 0 | L5: =(A5& ", "& B5& ", "& D5) -> 45689, 1, 4
A6: 45689 | B6: 1 | C6: Eataly Flatiron | D6: 5 | E6: Prosciutto e Melone | F6: 1911 | G6: 91 | H6: 6.9197656 | I6: 629.69867 | J6: 1281.3013 | K6: 0 | L6: =(A6& ", "& B6& ", "& D6) -> 45689, 1, 5
A7: 45689 | B7: 1 | C7: Eataly Flatiron | D7: 6 | E7: Bucatini all'Amatriciana | F7: 4071 | G7: 177 | H7: 4.6488076 | I7: 822.83895 | J7: 3248.161 | K7: 0 | L7: =(A7& ", "& B7& ", "& D7) -> 45689, 1, 6
A8: 45689 | B8: 1 | C8: Eataly Flatiron | D8: 7 | E8: Tiramisu | F8: 2236.5 | G8: 213 | H8: 2.7626657 | I8: 588.44779 | J8: 1648.0522 | K8: 0 | L8: =(A8& ", "& B8& ", "& D8) -> 45689, 1, 7
A9: 45689 | B9: 1 | C9: Eataly Flatiron | D9: 8 | E9: Focaccia Genovese | F9: 1725 | G9: 138 | H9: 0.68366991 | I9: 94.346447 | J9: 1630.6536 | K9: 0 | L9: =(A9& ", "& B9& ", "& D9) -> 45689, 1, 8
A10: 45689 | B10: 1 | C10: Eataly Flatiron | D10: 9 | E10: Osso Buco | F10: 3564 | G10: 72 | H10: 17.438853 | I10: 1255.5974 | J10: 2308.4026 | K10: 0 | L10: =(A10& ", "& B10& ", "& D10) -> 45689, 1, 9
A11: 45689 | B11: 1 | C11: Eataly Flatiron | D11: 10 | E11: Panzanella | F11: 1204 | G11: 86 | H11: 2.2652849 | I11: 194.81451 | J11: 1009.1855 | K11: 0 | L11: =(A11& ", "& B11& ", "& D11) -> 45689, 1, 10
A12: 45689 | B12: 1 | C12: Eataly Flatiron | D12: 11 | E12: Cacio e Pepe | F12: 3045 | G12: 145 | H12: 1.8611657 | I12: 269.86902 | J12: 2775.131 | K12: 0 | L12: =(A12& ", "& B12& ", "& D12) -> 45689, 1, 11
A13: 45689 | B13: 1 | C13: Eataly Flatiron | D13: 12 | E13: Pesto alla Genovese | F13: 2794 | G13: 127 | H13: 2.4998635 | I13: 317.48267 | J13: 2476.5173 | K13: 0 | L13: =(A13& ", "& B13& ", "& D13) -> 45689, 1, 12
A14: 45689 | B14: 1 | C14: Eataly Flatiron | D14: 13 | E14: Quattro Formaggi Pizza | F14: 4255 | G14: 185 | H14: 6.3790622 | I14: 1180.1265 | J14: 3074.8735 | K14: 0 | L14: =(A14& ", "& B14& ", "& D14) -> 45689, 1, 13
A15: 45689 | B15: 1 | C15: Eataly Flatiron | D15: 14 | E15: Porchetta | F15: 3556 | G15: 127 | H15: 4.5995654 | I15: 584.1448 | J15: 2971.8552 | K15: 0 | L15: =(A15& ", "& B15& ", "& D15) -> 45689, 1, 14
... A2638: 46266 | B2638: 8 | C2638: Eataly San Jose | D2638: 18 | E2638: Insalata di Mare | F2638: 828 | G2638: 36 | H2638: 6.2704994 | I2638: 225.73798 | J2638: 602.26202 | K2638: 0 | L2638: =(A2638& ", "& B2638& ", "& D2638) -> 46266, 8, 18

Sheet raw_location_price_variance
A1: location_id | B1: location_name | C1: month_start | D1: ingredient_id | E1: ingredient_name | F1: ingredient_category | G1: quantity_purchased | H1: purchase_dollars | I1: avg_price_paid | J1: max_purchase_price | K1: min_purchase_price | L1: total_orders
A2: 1 | B2: Eataly Flatiron | C2: 45689 | D2: 1 | E2: Extra Virgin Olive Oil | F2: Oil | G2: 12 | H2: 136.08 | I2: 11.34 | J2: 11.34 | K2: 11.34 | L2: 1 | N2: Sum of purchase_dollars
A3: 1 | B3: Eataly Flatiron | C3: 45717 | D3: 1 | E3: Extra Virgin Olive Oil | F3: Oil | G3: 24 | H3: 319.2 | I3: 13.3 | J3: 13.46 | K3: 13.14 | L3: 2 | N3: =SUM(H:H) -> 1577342.2
A4: 1 | B4: Eataly Flatiron | C4: 45748 | D4: 1 | E4: Extra Virgin Olive Oil | F4: Oil | G4: 24 | H4: 327.6 | I4: 13.65 | J4: 13.94 | K4: 13.36 | L4: 2
A5: 1 | B5: Eataly Flatiron | C5: 45778 | D5: 1 | E5: Extra Virgin Olive Oil | F5: Oil | G5: 24 | H5: 324.72 | I5: 13.53 | J5: 13.57 | K5: 13.49 | L5: 2
A6: 1 | B6: Eataly Flatiron | C6: 45809 | D6: 1 | E6: Extra Virgin Olive Oil | F6: Oil | G6: 24 | H6: 319.44 | I6: 13.31 | J6: 13.34 | K6: 13.28 | L6: 2
A7: 1 | B7: Eataly Flatiron | C7: 45839 | D7: 1 | E7: Extra Virgin Olive Oil | F7: Oil | G7: 24 | H7: 271.92 | I7: 11.33 | J7: 11.5 | K7: 11.16 | L7: 2
A8: 1 | B8: Eataly Flatiron | C8: 45870 | D8: 1 | E8: Extra Virgin Olive Oil | F8: Oil | G8: 24 | H8: 270.72 | I8: 11.28 | J8: 11.45 | K8: 11.11 | L8: 2
A9: 1 | B9: Eataly Flatiron | C9: 45901 | D9: 1 | E9: Extra Virgin Olive Oil | F9: Oil | G9: 24 | H9: 267.12 | I9: 11.13 | J9: 11.25 | K9: 11.01 | L9: 2
A10: 1 | B10: Eataly Flatiron | C10: 45931 | D10: 1 | E10: Extra Virgin Olive Oil | F10: Oil | G10: 24 | H10: 273.24 | I10: 11.385 | J10: 11.47 | K10: 11.3 | L10: 2
A11: 1 | B11: Eataly Flatiron | C11: 45962 | D11: 1 | E11: Extra Virgin Olive Oil | F11: Oil | G11: 24 | H11: 274.56 | I11: 11.44 | J11: 11.55 | K11: 11.33 | L11: 2
A12: 1 | B12: Eataly Flatiron | C12: 45992 | D12: 1 | E12: Extra Virgin Olive Oil | F12: Oil | G12: 36 | H12: 415.44 | I12: 11.54 | J12: 11.68 | K12: 11.41 | L12: 3
A13: 1 | B13: Eataly Flatiron | C13: 46023 | D13: 1 | E13: Extra Virgin Olive Oil | F13: Oil | G13: 12 | H13: 129.96 | I13: 10.83 | J13: 10.83 | K13: 10.83 | L13: 1
A14: 1 | B14: Eataly Flatiron | C14: 46054 | D14: 1 | E14: Extra Virgin Olive Oil | F14: Oil | G14: 24 | H14: 267.36 | I14: 11.14 | J14: 11.22 | K14: 11.06 | L14: 2
A15: 1 | B15: Eataly Flatiron | C15: 46082 | D15: 1 | E15: Extra Virgin Olive Oil | F15: Oil | G15: 24 | H15: 319.92 | I15: 13.33 | J15: 13.34 | K15: 13.32 | L15: 2
... A8016: 8 | B8016: Eataly San Jose | C8016: 46266 | D8016: 56 | E8016: Clams | F8016: Seafood | G8016: 8.5 | H8016: 68.935 | I8016: 8.11 | J8016: 8.26 | K8016: 8 | L8016: 7

Sheet raw_location_month_performance
A1: location_id | B1: location_name | C1: month_start | D1: sales_dollars | E1: year_over_year_change_pct | F1: tickets | G1: average_ticket_dollars | H1: actual_food_cost_dollars | I1: actual_food_cost_pct | J1: theoretical_food_cost_dollars | K1: theoretical_food_cost_pct | L1: purchase_food_cost_dollars | M1: purchase_food_cost_pct | N1: purchase_cost_gap_dollars | O1: purchase_cost_gap_pct | P1: actual_cost_gap_dollars | Q1: actual_cost_gap_pct | R1: estimated_price_ingredient_count | S1: unconverted_recipe_count
